/// In rx_rs, every extension has two version method. One version is use when no runtime error
/// will be propagated. This version receive an normal closure. The other is use when when will
/// propagating runtime error, named `err_with_xxx`, and receive an closure that return an
/// `Result` type, to detect if an runtime error occur.
///
/// In the inner of the extension, rx_rs not direct call the closureï¼Œbut via the `NextWithErr` or
/// `NextWithoutErr` to call `call_with_err` to execute the closure.
/// rx_rs unify the behavior of the two version through `NextWithErr` and `NextWithoutErr`.

pub trait WithErrByRef<T, R> {
  type Err;
  fn call_with_err(&self, v: &T) -> Result<R, Self::Err>;
}

pub trait WithErr<T, R> {
  type Err;
  fn call_with_err(&self, v: T) -> Result<R, Self::Err>;
}

pub struct NextWhitoutError<N>(pub N);

impl<T, R, N> WithErrByRef<T, R> for NextWhitoutError<N>
where
  N: Fn(&T) -> R,
{
  type Err = ();
  fn call_with_err(&self, v: &T) -> Result<R, Self::Err> {
    Ok(self.0(v))
  }
}

impl<T, R, N> WithErr<T, R> for NextWhitoutError<N>
where
  N: Fn(T) -> R,
{
  type Err = ();
  fn call_with_err(&self, v: T) -> Result<R, Self::Err> {
    Ok(self.0(v))
  }
}


pub struct NextWithError<NE>(pub NE);

impl<T, R, N, E> WithErrByRef<T, R> for NextWithError<N>
where
  N: Fn(&T) -> Result<R, E>,
{
  type Err = E;
  fn call_with_err(&self, v: &T) -> Result<R, Self::Err> {
    self.0(v)
  }
}

impl<T, R, N, E> WithErr<T, R> for NextWithError<N>
where
  N: Fn(T) -> Result<R, E>,
{
  type Err = E;
  fn call_with_err(&self, v: T) -> Result<R, Self::Err> {
    self.0(v)
  }
}
